Workbook
Name CategoryList: Inputs!$S$2:$S$9
Name PropertyList: Inputs!$A$3:$A$16

Sheet Dashboard
A1: Portfolio Dashboard
A3: Total properties | B3: =COUNTA(PropertyList)-1 -> 13 | V3: Property | W3: Current cap rate | X3: Gross Yield | Z3: Property | AA3: Target NOI | AB3: Actual NOI
A4: Total portfolio value (current) | B4: =IFERROR(SUM(Inputs!P3:P1001),0) -> 1681650 | V4: =Inputs!A3 -> 412 Elmwood Drive | W4: =Inputs!Q3 -> 0.095632184 | X4: =Inputs!O3 -> 0.53333333 | Z4: =Actuals!A2 -> 412 Elmwood Drive | AA4: =Actuals!H2 -> 693.33333 | AB4: =IF(Actuals!I2="No data",0,Actuals!I2) -> 884.804
A5: Total monthly income | B5: =IFERROR(SUM(Inputs!I3:I1001),0) -> 11333.75 | V5: =Inputs!A4 -> 728 Chestnut Lane | W5: =Inputs!Q4 -> 0.10064516 | X5: =Inputs!O4 -> 0.56842105 | Z5: =Actuals!A3 -> 728 Chestnut Lane | AA5: =Actuals!H3 -> 780 | AB5: =IF(Actuals!I3="No data",0,Actuals!I3) -> 1080
A6: Total annual NOI | B6: =IFERROR(SUM(Inputs!L3:L1001),0) -> 94089.287 | V6: =Inputs!A5 -> 1053 Ridgeway Avenue | W6: =Inputs!Q5 -> 0.072496454 | X6: =Inputs!O5 -> 0.51818182 | Z6: =Actuals!A4 -> 1053 Ridgeway Avenue | AA6: =Actuals!H4 -> 425.91667 | AB6: =IF(Actuals!I4="No data",0,Actuals!I4) -> 570
A7: Average current cap rate | B7: =IFERROR(AVERAGE(Inputs!Q3:Q1001),0) -> 0.071022511 | V7: =Inputs!A6 -> 309 Birchwood Court | W7: =Inputs!Q6 -> 0.084947368 | X7: =Inputs!O6 -> 0.58064516 | Z7: =Actuals!A5 -> 309 Birchwood Court | AA7: =Actuals!H5 -> 672.5 | AB7: =IF(Actuals!I5="No data",0,Actuals!I5) -> 881.082
A8: Average cash-on-cash return | B8: =IFERROR(AVERAGE(Inputs!N3:N1001),0) -> 0.41153637 | V8: =Inputs!A7 -> 847 Sycamore Street | W8: =Inputs!Q7 -> 0.081568627 | X8: =Inputs!O7 -> 0.51428571 | Z8: =Actuals!A6 -> 847 Sycamore Street | AA8: =Actuals!H6 -> 780 | AB8: =IF(Actuals!I6="No data",0,Actuals!I6) -> 1067.23
A9: Average gross yield | B9: =IFERROR(AVERAGE(Inputs!O3:O1001),0) -> 0.47162274 | V9: =Inputs!A8 -> 215 Hollow Creek Road | W9: =Inputs!Q8 -> 0.086068966 | X9: =Inputs!O8 -> 0.65454545 | Z9: =Actuals!A7 -> 215 Hollow Creek Road | AA9: =Actuals!H7 -> 780 | AB9: =IF(Actuals!I7="No data",0,Actuals!I7) -> 1032.052
V10: =Inputs!A9 -> 634 Pinecrest Boulevard | W10: =Inputs!Q9 -> 0.11319728 | X10: =Inputs!O9 -> 0.64 | Z10: =Actuals!A8 -> 634 Pinecrest Boulevard | AA10: =Actuals!H8 -> 693.33333 | AB10: =IF(Actuals!I8="No data",0,Actuals!I8) -> 956.086
A11: Portfolio Performance: Budget vs. Actual | V11: =Inputs!A10 -> 491 Maplewood Circle | W11: =Inputs!Q10 -> 0.047570526 | X11: =Inputs!O10 -> 0.525 | Z11: =Actuals!A9 -> 491 Maplewood Circle | AA11: =Actuals!H9 -> 470.75 | AB11: =IF(Actuals!I9="No data",0,Actuals!I9) -> 630
V12: =Inputs!A11 -> 1127 Cedarhill Drive | W12: =Inputs!Q11 -> 0.076338515 | X12: =Inputs!O11 -> 0.78461538 | Z12: =Actuals!A10 -> 1127 Cedarhill Drive | AA12: =Actuals!H10 -> 736.66667 | AB12: =IF(Actuals!I10="No data",0,Actuals!I10) -> 844.142
A13: Rent variance | B13: =IFERROR(SUMIF(Actuals!D2:D1000,"<>No data",Actuals!D2:D1000),0) -> 1715 | V13: =Inputs!A12 -> 376 Walnut Grove Lane | W13: =Inputs!Q12 -> 0.080436761 | X13: =Inputs!O12 -> 0.58285714 | Z13: =Actuals!A11 -> 376 Walnut Grove Lane | AA13: =Actuals!H11 -> 736.66667 | AB13: =IF(Actuals!I11="No data",0,Actuals!I11) -> 630
A14: Expense variance | B14: =IFERROR(SUMIF(Actuals!G2:G1000,"<>No data",Actuals!G2:G1000),0) -> -594.97933 | V14: =Inputs!A13 -> 823 Thornberry Street | W14: =Inputs!Q13 -> 0.057655755 | X14: =Inputs!O13 -> 0.525 | Z14: =Actuals!A12 -> 823 Thornberry Street | AA14: =Actuals!H12 -> 455 | AB14: =IF(Actuals!I12="No data",0,Actuals!I12) -> 1020
A15: NOI variance | B15: =IFERROR(SUMIF(Actuals!J2:J1000,"<>No data",Actuals!J2:J1000),0) -> 2371.2293 | V15: =Inputs!A14 -> Mid-range Test Prop | W15: =Inputs!Q14 -> 0.016473664 | X15: =Inputs!O14 -> 0.093333333 | Z15: =Actuals!A13 -> Mid-range Test Prop | AA15: =Actuals!H13 -> 274.56106 | AB15: =IF(Actuals!I13="No data",0,Actuals!I13) -> 0
A16: Properties underperforming | B16: =IFERROR(COUNTIF(Actuals!J2:J1000,"<0"),0) -> 1 | C16: Variance metrics reflect 7 of 13 properties with logged 2026 data | V16: =Inputs!A15 -> High-end Test Prop | W16: =Inputs!Q15 -> 0.010261386 | X16: =Inputs!O15 -> 0.0825 | Z16: =Actuals!A14 -> High-end Test Prop | AA16: =Actuals!H14 -> 342.04622 | AB16: =IF(Actuals!I14="No data",0,Actuals!I14) -> 0
K30: Data sources: Property values via Zillow estimates as of May 2026.
K31: Expenses are estimates where actuals unavailable.

Sheet Actuals
A1: Property | B1: Target rent | C1: Actual rent collected | D1: Rent variance | E1: Target expenses | F1: Actual expenses | G1: Expense variance | H1: Target NOI | I1: Actual NOI | J1: NOI variance
A2: =Inputs!A3 -> 412 Elmwood Drive | B2: =IFERROR(Inputs!F3,"N/A") -> 800 | C2: =IFERROR(IF(SUMIF('Rent Collections'!$B$2:$B$10007,A2,'Rent Collections'!$E$2:$E$10007)=0,"No data",SUMIF('Rent Collections'!$B$2:$B$10007,A2,'Rent Collections'!$E$2:$E$10007)/(COUNTIFS('Rent Collections'!$B$2:$B$10000,"1053 Ridgeway Avenue")-1)),"No data") -> 960 | D2: =IFERROR(IF(C2="No data","No data",C2-B2),"No data") -> 160 | E2: =IFERROR(Inputs!H3,"N/A") -> 66.666667 | F2: =IFERROR(IF(SUMIF(Expenses!$B$2:$B$10002,A2,Expenses!$E$2:$E$10002)=0,0,SUMIF(Expenses!$B$2:$B$10002,A2,Expenses!$E$2:$E$10002)/(COUNTIFS('Rent Collections'!$B$2:$B$10000,"1053 Ridgeway Avenue")-1)),"0") -> 75.196 | G2: =IFERROR(IF(F2="No data","No data",F2-E2),"No data") -> 8.5293333 | H2: =IFERROR(Inputs!K3,"N/A") -> 693.33333 | I2: =IFERROR(IF(OR(C2="No data",F2="No data"),"No data",C2-F2),"No data") -> 884.804 | J2: =IFERROR(IF(I2="No data","No data",I2-H2),"No data") -> 191.47067
A3: =Inputs!A4 -> 728 Chestnut Lane | B3: =IFERROR(Inputs!F4,"N/A") -> 900 | C3: =IFERROR(IF(SUMIF('Rent Collections'!$B$2:$B$10007,A3,'Rent Collections'!$E$2:$E$10007)=0,"No data",SUMIF('Rent Collections'!$B$2:$B$10007,A3,'Rent Collections'!$E$2:$E$10007)/(COUNTIFS('Rent Collections'!$B$2:$B$10000,"1053 Ridgeway Avenue")-1)),"No data") -> 1080 | D3: =IFERROR(IF(C3="No data","No data",C3-B3),"No data") -> 180 | E3: =IFERROR(Inputs!H4,"N/A") -> 75 | F3: =IFERROR(IF(SUMIF(Expenses!$B$2:$B$10002,A3,Expenses!$E$2:$E$10002)=0,0,SUMIF(Expenses!$B$2:$B$10002,A3,Expenses!$E$2:$E$10002)/(COUNTIFS('Rent Collections'!$B$2:$B$10000,"1053 Ridgeway Avenue")-1)),"0") -> 0 | G3: =IFERROR(IF(F3="No data","No data",F3-E3),"No data") -> -75 | H3: =IFERROR(Inputs!K4,"N/A") -> 780 | I3: =IFERROR(IF(OR(C3="No data",F3="No data"),"No data",C3-F3),"No data") -> 1080 | J3: =IFERROR(IF(I3="No data","No data",I3-H3),"No data") -> 300
A4: =Inputs!A5 -> 1053 Ridgeway Avenue | B4: =IFERROR(Inputs!F5,"N/A") -> 475 | C4: =IFERROR(IF(SUMIF('Rent Collections'!$B$2:$B$10007,A4,'Rent Collections'!$E$2:$E$10007)=0,"No data",SUMIF('Rent Collections'!$B$2:$B$10007,A4,'Rent Collections'!$E$2:$E$10007)/(COUNTIFS('Rent Collections'!$B$2:$B$10000,"1053 Ridgeway Avenue")-1)),"No data") -> 570 | D4: =IFERROR(IF(C4="No data","No data",C4-B4),"No data") -> 95 | E4: =IFERROR(Inputs!H5,"N/A") -> 39.583333 | F4: =IFERROR(IF(SUMIF(Expenses!$B$2:$B$10002,A4,Expenses!$E$2:$E$10002)=0,0,SUMIF(Expenses!$B$2:$B$10002,A4,Expenses!$E$2:$E$10002)/(COUNTIFS('Rent Collections'!$B$2:$B$10000,"1053 Ridgeway Avenue")-1)),"0") -> 0 | G4: =IFERROR(IF(F4="No data","No data",F4-E4),"No data") -> -39.583333 | H4: =IFERROR(Inputs!K5,"N/A") -> 425.91667 | I4: =IFERROR(IF(OR(C4="No data",F4="No data"),"No data",C4-F4),"No data") -> 570 | J4: =IFERROR(IF(I4="No data","No data",I4-H4),"No data") -> 144.08333
A5: =Inputs!A6 -> 309 Birchwood Court | B5: =IFERROR(Inputs!F6,"N/A") -> 750 | C5: =IFERROR(IF(SUMIF('Rent Collections'!$B$2:$B$10007,A5,'Rent Collections'!$E$2:$E$10007)=0,"No data",SUMIF('Rent Collections'!$B$2:$B$10007,A5,'Rent Collections'!$E$2:$E$10007)/(COUNTIFS('Rent Collections'!$B$2:$B$10000,"1053 Ridgeway Avenue")-1)),"No data") -> 900 | D5: =IFERROR(IF(C5="No data","No data",C5-B5),"No data") -> 150 | E5: =IFERROR(Inputs!H6,"N/A") -> 62.5 | F5: =IFERROR(IF(SUMIF(Expenses!$B$2:$B$10002,A5,Expenses!$E$2:$E$10002)=0,0,SUMIF(Expenses!$B$2:$B$10002,A5,Expenses!$E$2:$E$10002)/(COUNTIFS('Rent Collections'!$B$2:$B$10000,"1053 Ridgeway Avenue")-1)),"0") -> 18.918 | G5: =IFERROR(IF(F5="No data","No data",F5-E5),"No data") -> -43.582 | H5: =IFERROR(Inputs!K6,"N/A") -> 672.5 | I5: =IFERROR(IF(OR(C5="No data",F5="No data"),"No data",C5-F5),"No data") -> 881.082 | J5: =IFERROR(IF(I5="No data","No data",I5-H5),"No data") -> 208.582
A6: =Inputs!A7 -> 847 Sycamore Street | B6: =IFERROR(Inputs!F7,"N/A") -> 900 | C6: =IFERROR(IF(SUMIF('Rent Collections'!$B$2:$B$10007,A6,'Rent Collections'!$E$2:$E$10007)=0,"No data",SUMIF('Rent Collections'!$B$2:$B$10007,A6,'Rent Collections'!$E$2:$E$10007)/(COUNTIFS('Rent Collections'!$B$2:$B$10000,"1053 Ridgeway Avenue")-1)),"No data") -> 1105 | D6: =IFERROR(IF(C6="No data","No data",C6-B6),"No data") -> 205 | E6: =IFERROR(Inputs!H7,"N/A") -> 75 | F6: =IFERROR(IF(SUMIF(Expenses!$B$2:$B$10002,A6,Expenses!$E$2:$E$10002)=0,0,SUMIF(Expenses!$B$2:$B$10002,A6,Expenses!$E$2:$E$10002)/(COUNTIFS('Rent Collections'!$B$2:$B$10000,"1053 Ridgeway Avenue")-1)),"0") -> 37.77 | G6: =IFERROR(IF(F6="No data","No data",F6-E6),"No data") -> -37.23 | H6: =IFERROR(Inputs!K7,"N/A") -> 780 | I6: =IFERROR(IF(OR(C6="No data",F6="No data"),"No data",C6-F6),"No data") -> 1067.23 | J6: =IFERROR(IF(I6="No data","No data",I6-H6),"No data") -> 287.23
A7: =Inputs!A8 -> 215 Hollow Creek Road | B7: =IFERROR(Inputs!F8,"N/A") -> 900 | C7: =IFERROR(IF(SUMIF('Rent Collections'!$B$2:$B$10007,A7,'Rent Collections'!$E$2:$E$10007)=0,"No data",SUMIF('Rent Collections'!$B$2:$B$10007,A7,'Rent Collections'!$E$2:$E$10007)/(COUNTIFS('Rent Collections'!$B$2:$B$10000,"1053 Ridgeway Avenue")-1)),"No data") -> 1115 | D7: =IFERROR(IF(C7="No data","No data",C7-B7),"No data") -> 215 | E7: =IFERROR(Inputs!H8,"N/A") -> 75 | F7: =IFERROR(IF(SUMIF(Expenses!$B$2:$B$10002,A7,Expenses!$E$2:$E$10002)=0,0,SUMIF(Expenses!$B$2:$B$10002,A7,Expenses!$E$2:$E$10002)/(COUNTIFS('Rent Collections'!$B$2:$B$10000,"1053 Ridgeway Avenue")-1)),"0") -> 82.948 | G7: =IFERROR(IF(F7="No data","No data",F7-E7),"No data") -> 7.948 | H7: =IFERROR(Inputs!K8,"N/A") -> 780 | I7: =IFERROR(IF(OR(C7="No data",F7="No data"),"No data",C7-F7),"No data") -> 1032.052 | J7: =IFERROR(IF(I7="No data","No data",I7-H7),"No data") -> 252.052
A8: =Inputs!A9 -> 634 Pinecrest Boulevard | B8: =IFERROR(Inputs!F9,"N/A") -> 800 | C8: =IFERROR(IF(SUMIF('Rent Collections'!$B$2:$B$10007,A8,'Rent Collections'!$E$2:$E$10007)=0,"No data",SUMIF('Rent Collections'!$B$2:$B$10007,A8,'Rent Collections'!$E$2:$E$10007)/(COUNTIFS('Rent Collections'!$B$2:$B$10000,"1053 Ridgeway Avenue")-1)),"No data") -> 960 | D8: =IFERROR(IF(C8="No data","No data",C8-B8),"No data") -> 160 | E8: =IFERROR(Inputs!H9,"N/A") -> 66.666667 | F8: =IFERROR(IF(SUMIF(Expenses!$B$2:$B$10002,A8,Expenses!$E$2:$E$10002)=0,0,SUMIF(Expenses!$B$2:$B$10002,A8,Expenses!$E$2:$E$10002)/(COUNTIFS('Rent Collections'!$B$2:$B$10000,"1053 Ridgeway Avenue")-1)),"0") -> 3.914 | G8: =IFERROR(IF(F8="No data","No data",F8-E8),"No data") -> -62.752667 | H8: =IFERROR(Inputs!K9,"N/A") -> 693.33333 | I8: =IFERROR(IF(OR(C8="No data",F8="No data"),"No data",C8-F8),"No data") -> 956.086 | J8: =IFERROR(IF(I8="No data","No data",I8-H8),"No data") -> 262.75267
A9: =Inputs!A10 -> 491 Maplewood Circle | B9: =IFERROR(Inputs!F10,"N/A") -> 525 | C9: =IFERROR(IF(SUMIF('Rent Collections'!$B$2:$B$10007,A9,'Rent Collections'!$E$2:$E$10007)=0,"No data",SUMIF('Rent Collections'!$B$2:$B$10007,A9,'Rent Collections'!$E$2:$E$10007)/(COUNTIFS('Rent Collections'!$B$2:$B$10000,"1053 Ridgeway Avenue")-1)),"No data") -> 630 | D9: =IFERROR(IF(C9="No data","No data",C9-B9),"No data") -> 105 | E9: =IFERROR(Inputs!H10,"N/A") -> 43.75 | F9: =IFERROR(IF(SUMIF(Expenses!$B$2:$B$10002,A9,Expenses!$E$2:$E$10002)=0,0,SUMIF(Expenses!$B$2:$B$10002,A9,Expenses!$E$2:$E$10002)/(COUNTIFS('Rent Collections'!$B$2:$B$10000,"1053 Ridgeway Avenue")-1)),"0") -> 0 | G9: =IFERROR(IF(F9="No data","No data",F9-E9),"No data") -> -43.75 | H9: =IFERROR(Inputs!K10,"N/A") -> 470.75 | I9: =IFERROR(IF(OR(C9="No data",F9="No data"),"No data",C9-F9),"No data") -> 630 | J9: =IFERROR(IF(I9="No data","No data",I9-H9),"No data") -> 159.25
A10: =Inputs!A11 -> 1127 Cedarhill Drive | B10: =IFERROR(Inputs!F11,"N/A") -> 850 | C10: =IFERROR(IF(SUMIF('Rent Collections'!$B$2:$B$10007,A10,'Rent Collections'!$E$2:$E$10007)=0,"No data",SUMIF('Rent Collections'!$B$2:$B$10007,A10,'Rent Collections'!$E$2:$E$10007)/(COUNTIFS('Rent Collections'!$B$2:$B$10000,"1053 Ridgeway Avenue")-1)),"No data") -> 1020 | D10: =IFERROR(IF(C10="No data","No data",C10-B10),"No data") -> 170 | E10: =IFERROR(Inputs!H11,"N/A") -> 70.833333 | F10: =IFERROR(IF(SUMIF(Expenses!$B$2:$B$10002,A10,Expenses!$E$2:$E$10002)=0,0,SUMIF(Expenses!$B$2:$B$10002,A10,Expenses!$E$2:$E$10002)/(COUNTIFS('Rent Collections'!$B$2:$B$10000,"1053 Ridgeway Avenue")-1)),"0") -> 175.858 | G10: =IFERROR(IF(F10="No data","No data",F10-E10),"No data") -> 105.02467 | H10: =IFERROR(Inputs!K11,"N/A") -> 736.66667 | I10: =IFERROR(IF(OR(C10="No data",F10="No data"),"No data",C10-F10),"No data") -> 844.142 | J10: =IFERROR(IF(I10="No data","No data",I10-H10),"No data") -> 107.47533
A11: =Inputs!A12 -> 376 Walnut Grove Lane | B11: =IFERROR(Inputs!F12,"N/A") -> 850 | C11: =IFERROR(IF(SUMIF('Rent Collections'!$B$2:$B$10007,A11,'Rent Collections'!$E$2:$E$10007)=0,"No data",SUMIF('Rent Collections'!$B$2:$B$10007,A11,'Rent Collections'!$E$2:$E$10007)/(COUNTIFS('Rent Collections'!$B$2:$B$10000,"1053 Ridgeway Avenue")-1)),"No data") -> 630 | D11: =IFERROR(IF(C11="No data","No data",C11-B11),"No data") -> -220 | E11: =IFERROR(Inputs!H12,"N/A") -> 70.833333 | F11: =IFERROR(IF(SUMIF(Expenses!$B$2:$B$10002,A11,Expenses!$E$2:$E$10002)=0,0,SUMIF(Expenses!$B$2:$B$10002,A11,Expenses!$E$2:$E$10002)/(COUNTIFS('Rent Collections'!$B$2:$B$10000,"1053 Ridgeway Avenue")-1)),"0") -> 0 | G11: =IFERROR(IF(F11="No data","No data",F11-E11),"No data") -> -70.833333 | H11: =IFERROR(Inputs!K12,"N/A") -> 736.66667 | I11: =IFERROR(IF(OR(C11="No data",F11="No data"),"No data",C11-F11),"No data") -> 630 | J11: =IFERROR(IF(I11="No data","No data",I11-H11),"No data") -> -106.66667
A12: =Inputs!A13 -> 823 Thornberry Street | B12: =IFERROR(Inputs!F13,"N/A") -> 525 | C12: =IFERROR(IF(SUMIF('Rent Collections'!$B$2:$B$10007,A12,'Rent Collections'!$E$2:$E$10007)=0,"No data",SUMIF('Rent Collections'!$B$2:$B$10007,A12,'Rent Collections'!$E$2:$E$10007)/(COUNTIFS('Rent Collections'!$B$2:$B$10000,"1053 Ridgeway Avenue")-1)),"No data") -> 1020 | D12: =IFERROR(IF(C12="No data","No data",C12-B12),"No data") -> 495 | E12: =IFERROR(Inputs!H13,"N/A") -> 43.75 | F12: =IFERROR(IF(SUMIF(Expenses!$B$2:$B$10002,A12,Expenses!$E$2:$E$10002)=0,0,SUMIF(Expenses!$B$2:$B$10002,A12,Expenses!$E$2:$E$10002)/(COUNTIFS('Rent Collections'!$B$2:$B$10000,"1053 Ridgeway Avenue")-1)),"0") -> 0 | G12: =IFERROR(IF(F12="No data","No data",F12-E12),"No data") -> -43.75 | H12: =IFERROR(Inputs!K13,"N/A") -> 455 | I12: =IFERROR(IF(OR(C12="No data",F12="No data"),"No data",C12-F12),"No data") -> 1020 | J12: =IFERROR(IF(I12="No data","No data",I12-H12),"No data") -> 565
A13: =Inputs!A14 -> Mid-range Test Prop | B13: =IFERROR(Inputs!F14,"N/A") -> 1400 | C13: =IFERROR(IF(SUMIF('Rent Collections'!$B$2:$B$10007,A13,'Rent Collections'!$E$2:$E$10007)=0,"No data",SUMIF('Rent Collections'!$B$2:$B$10007,A13,'Rent Collections'!$E$2:$E$10007)/(COUNTIFS('Rent Collections'!$B$2:$B$10000,"1053 Ridgeway Avenue")-1)),"No data") -> No data | D13: =IFERROR(IF(C13="No data","No data",C13-B13),"No data") -> No data | E13: =IFERROR(Inputs!H14,"N/A") -> 116.66667 | F13: =IFERROR(IF(SUMIF(Expenses!$B$2:$B$10002,A13,Expenses!$E$2:$E$10002)=0,0,SUMIF(Expenses!$B$2:$B$10002,A13,Expenses!$E$2:$E$10002)/(COUNTIFS('Rent Collections'!$B$2:$B$10000,"1053 Ridgeway Avenue")-1)),"0") -> 0 | G13: =IFERROR(IF(F13="No data","No data",F13-E13),"No data") -> -116.66667 | H13: =IFERROR(Inputs!K14,"N/A") -> 274.56106 | I13: =IFERROR(IF(OR(C13="No data",F13="No data"),"No data",C13-F13),"No data") -> No data | J13: =IFERROR(IF(I13="No data","No data",I13-H13),"No data") -> No data
A14: =Inputs!A15 -> High-end Test Prop | B14: =IFERROR(Inputs!F15,"N/A") -> 2200 | C14: =IFERROR(IF(SUMIF('Rent Collections'!$B$2:$B$10007,A14,'Rent Collections'!$E$2:$E$10007)=0,"No data",SUMIF('Rent Collections'!$B$2:$B$10007,A14,'Rent Collections'!$E$2:$E$10007)/(COUNTIFS('Rent Collections'!$B$2:$B$10000,"1053 Ridgeway Avenue")-1)),"No data") -> No data | D14: =IFERROR(IF(C14="No data","No data",C14-B14),"No data") -> No data | E14: =IFERROR(Inputs!H15,"N/A") -> 183.33333 | F14: =IFERROR(IF(SUMIF(Expenses!$B$2:$B$10002,A14,Expenses!$E$2:$E$10002)=0,0,SUMIF(Expenses!$B$2:$B$10002,A14,Expenses!$E$2:$E$10002)/(COUNTIFS('Rent Collections'!$B$2:$B$10000,"1053 Ridgeway Avenue")-1)),"0") -> 0 | G14: =IFERROR(IF(F14="No data","No data",F14-E14),"No data") -> -183.33333 | H14: =IFERROR(Inputs!K15,"N/A") -> 342.04622 | I14: =IFERROR(IF(OR(C14="No data",F14="No data"),"No data",C14-F14),"No data") -> No data | J14: =IFERROR(IF(I14="No data","No data",I14-H14),"No data") -> No data

Sheet Inputs
A1: Real Estate Portfolio Analysis
A2: Property Address | B2: Purchase Price | C2: Down payment (%) | D2: Loan term (years) | E2: Interest rate (%) | F2: Monthly rent | G2: Vacancy rate (%) | H2: Monthly expenses | I2: Effective monthly rent | J2: Monthly Mortgage | K2: Monthly NOI | L2: Annual NOI | M2: Purchase Cap Rate | N2: Cash-on-cash return | O2: Gross Yield | P2: Current estimate value (Zillow) | Q2: Current cap rate
A3: 412 Elmwood Drive | B3: 18000 | C3: 1 | D3: 0 | E3: 0 | F3: 800 | G3: 0.05 | H3: =F3/12 -> 66.666667 | I3: =IFERROR(F3*(1-G3),0) -> 760 | J3: =IFERROR(IF(D3=0,0,PMT(E3/12,D3*12,-(B3*(1-C3)))),0) -> 0 | K3: =IFERROR(I3-J3-H3,0) -> 693.33333 | L3: =IFERROR(K3*12,0) -> 8320 | M3: =IFERROR(L3/B3,0) -> 0.46222222 | N3: =IFERROR(L3/(B3*C3),0) -> 0.46222222 | O3: =IFERROR((F3*12)/B3,0) -> 0.53333333 | P3: 87000 | Q3: =IFERROR(L3/P3,0) -> 0.095632184
A4: 728 Chestnut Lane | B4: 19000 | C4: 1 | D4: 0 | E4: 0 | F4: 900 | G4: 0.05 | H4: =F4/12 -> 75 | I4: =IFERROR(F4*(1-G4),0) -> 855 | J4: =IFERROR(IF(D4=0,0,PMT(E4/12,D4*12,-(B4*(1-C4)))),0) -> 0 | K4: =IFERROR(I4-J4-H4,0) -> 780 | L4: =IFERROR(K4*12,0) -> 9360 | M4: =IFERROR(L4/B4,0) -> 0.49263158 | N4: =IFERROR(L4/(B4*C4),0) -> 0.49263158 | O4: =IFERROR((F4*12)/B4,0) -> 0.56842105 | P4: 93000 | Q4: =IFERROR(L4/P4,0) -> 0.10064516
A5: 1053 Ridgeway Avenue | B5: 11000 | C5: 1 | D5: 0 | E5: 0 | F5: 475 | G5: 0.02 | H5: =F5/12 -> 39.583333 | I5: =IFERROR(F5*(1-G5),0) -> 465.5 | J5: =IFERROR(IF(D5=0,0,PMT(E5/12,D5*12,-(B5*(1-C5)))),0) -> 0 | K5: =IFERROR(I5-J5-H5,0) -> 425.91667 | L5: =IFERROR(K5*12,0) -> 5111 | M5: =IFERROR(L5/B5,0) -> 0.46463636 | N5: =IFERROR(L5/(B5*C5),0) -> 0.46463636 | O5: =IFERROR((F5*12)/B5,0) -> 0.51818182 | P5: 70500 | Q5: =IFERROR(L5/P5,0) -> 0.072496454
A6: 309 Birchwood Court | B6: 15500 | C6: 1 | D6: 0 | E6: 0 | F6: 750 | G6: 0.02 | H6: =F6/12 -> 62.5 | I6: =IFERROR(F6*(1-G6),0) -> 735 | J6: =IFERROR(IF(D6=0,0,PMT(E6/12,D6*12,-(B6*(1-C6)))),0) -> 0 | K6: =IFERROR(I6-J6-H6,0) -> 672.5 | L6: =IFERROR(K6*12,0) -> 8070 | M6: =IFERROR(L6/B6,0) -> 0.52064516 | N6: =IFERROR(L6/(B6*C6),0) -> 0.52064516 | O6: =IFERROR((F6*12)/B6,0) -> 0.58064516 | P6: 95000 | Q6: =IFERROR(L6/P6,0) -> 0.084947368
A7: 847 Sycamore Street | B7: 21000 | C7: 1 | D7: 0 | E7: 0 | F7: 900 | G7: 0.05 | H7: =F7/12 -> 75 | I7: =IFERROR(F7*(1-G7),0) -> 855 | J7: =IFERROR(IF(D7=0,0,PMT(E7/12,D7*12,-(B7*(1-C7)))),0) -> 0 | K7: =IFERROR(I7-J7-H7,0) -> 780 | L7: =IFERROR(K7*12,0) -> 9360 | M7: =IFERROR(L7/B7,0) -> 0.44571429 | N7: =IFERROR(L7/(B7*C7),0) -> 0.44571429 | O7: =IFERROR((F7*12)/B7,0) -> 0.51428571 | P7: 114750 | Q7: =IFERROR(L7/P7,0) -> 0.081568627
A8: 215 Hollow Creek Road | B8: 16500 | C8: 1 | D8: 0 | E8: 0 | F8: 900 | G8: 0.05 | H8: =F8/12 -> 75 | I8: =IFERROR(F8*(1-G8),0) -> 855 | J8: =IFERROR(IF(D8=0,0,PMT(E8/12,D8*12,-(B8*(1-C8)))),0) -> 0 | K8: =IFERROR(I8-J8-H8,0) -> 780 | L8: =IFERROR(K8*12,0) -> 9360 | M8: =IFERROR(L8/B8,0) -> 0.56727273 | N8: =IFERROR(L8/(B8*C8),0) -> 0.56727273 | O8: =IFERROR((F8*12)/B8,0) -> 0.65454545 | P8: 108750 | Q8: =IFERROR(L8/P8,0) -> 0.086068966
A9: 634 Pinecrest Boulevard | B9: 15000 | C9: 1 | D9: 0 | E9: 0 | F9: 800 | G9: 0.05 | H9: =F9/12 -> 66.666667 | I9: =IFERROR(F9*(1-G9),0) -> 760 | J9: =IFERROR(IF(D9=0,0,PMT(E9/12,D9*12,-(B9*(1-C9)))),0) -> 0 | K9: =IFERROR(I9-J9-H9,0) -> 693.33333 | L9: =IFERROR(K9*12,0) -> 8320 | M9: =IFERROR(L9/B9,0) -> 0.55466667 | N9: =IFERROR(L9/(B9*C9),0) -> 0.55466667 | O9: =IFERROR((F9*12)/B9,0) -> 0.64 | P9: 73500 | Q9: =IFERROR(L9/P9,0) -> 0.11319728
A10: 491 Maplewood Circle | B10: 12000 | C10: 1 | D10: 0 | E10: 0 | F10: 525 | G10: 0.02 | H10: =F10/12 -> 43.75 | I10: =IFERROR(F10*(1-G10),0) -> 514.5 | J10: =IFERROR(IF(D10=0,0,PMT(E10/12,D10*12,-(B10*(1-C10)))),0) -> 0 | K10: =IFERROR(I10-J10-H10,0) -> 470.75 | L10: =IFERROR(K10*12,0) -> 5649 | M10: =IFERROR(L10/B10,0) -> 0.47075 | N10: =IFERROR(L10/(B10*C10),0) -> 0.47075 | O10: =IFERROR((F10*12)/B10,0) -> 0.525 | P10: 118750 | Q10: =IFERROR(L10/P10,0) -> 0.047570526
A11: 1127 Cedarhill Drive | B11: 13000 | C11: 1 | D11: 0 | E11: 0 | F11: 850 | G11: 0.05 | H11: =F11/12 -> 70.833333 | I11: =IFERROR(F11*(1-G11),0) -> 807.5 | J11: =IFERROR(IF(D11=0,0,PMT(E11/12,D11*12,-(B11*(1-C11)))),0) -> 0 | K11: =IFERROR(I11-J11-H11,0) -> 736.66667 | L11: =IFERROR(K11*12,0) -> 8840 | M11: =IFERROR(L11/B11,0) -> 0.68 | N11: =IFERROR(L11/(B11*C11),0) -> 0.68 | O11: =IFERROR((F11*12)/B11,0) -> 0.78461538 | P11: 115800 | Q11: =IFERROR(L11/P11,0) -> 0.076338515
A12: 376 Walnut Grove Lane | B12: 17500 | C12: 1 | D12: 0 | E12: 0 | F12: 850 | G12: 0.05 | H12: =F12/12 -> 70.833333 | I12: =IFERROR(F12*(1-G12),0) -> 807.5 | J12: =IFERROR(IF(D12=0,0,PMT(E12/12,D12*12,-(B12*(1-C12)))),0) -> 0 | K12: =IFERROR(I12-J12-H12,0) -> 736.66667 | L12: =IFERROR(K12*12,0) -> 8840 | M12: =IFERROR(L12/B12,0) -> 0.50514286 | N12: =IFERROR(L12/(B12*C12),0) -> 0.50514286 | O12: =IFERROR((F12*12)/B12,0) -> 0.58285714 | P12: 109900 | Q12: =IFERROR(L12/P12,0) -> 0.080436761
A13: 823 Thornberry Street | B13: 12000 | C13: 1 | D13: 0 | E13: 0 | F13: 525 | G13: 0.05 | H13: =F13/12 -> 43.75 | I13: =IFERROR(F13*(1-G13),0) -> 498.75 | J13: =IFERROR(IF(D13=0,0,PMT(E13/12,D13*12,-(B13*(1-C13)))),0) -> 0 | K13: =IFERROR(I13-J13-H13,0) -> 455 | L13: =IFERROR(K13*12,0) -> 5460 | M13: =IFERROR(L13/B13,0) -> 0.455 | N13: =IFERROR(L13/(B13*C13),0) -> 0.455 | O13: =IFERROR((F13*12)/B13,0) -> 0.525 | P13: 94700 | Q13: =IFERROR(L13/P13,0) -> 0.057655755
A14: Mid-range Test Prop | B14: 180000 | C14: 0.2 | D14: 30 | E14: 0.068 | F14: 1400 | G14: 0.05 | H14: =F14/12 -> 116.66667 | I14: =IFERROR(F14*(1-G14),0) -> 1330 | J14: =IFERROR(IF(D14=0,0,PMT(E14/12,D14*12,-(B14*(1-C14)))),0) -> 938.77227 | K14: =IFERROR(I14-J14-H14,0) -> 274.56106 | L14: =IFERROR(K14*12,0) -> 3294.7327 | M14: =IFERROR(L14/B14,0) -> 0.018304071 | N14: =IFERROR(L14/(B14*C14),0) -> 0.091520354 | O14: =IFERROR((F14*12)/B14,0) -> 0.093333333 | P14: 200000 | Q14: =IFERROR(L14/P14,0) -> 0.016473664
A15: High-end Test Prop | B15: 320000 | C15: 0.25 | D15: 30 | E15: 0.068 | F15: 2200 | G15: 0.05 | H15: =F15/12 -> 183.33333 | I15: =IFERROR(F15*(1-G15),0) -> 2090 | J15: =IFERROR(IF(D15=0,0,PMT(E15/12,D15*12,-(B15*(1-C15)))),0) -> 1564.6205 | K15: =IFERROR(I15-J15-H15,0) -> 342.04622 | L15: =IFERROR(K15*12,0) -> 4104.5546 | M15: =IFERROR(L15/B15,0) -> 0.012826733 | N15: =IFERROR(L15/(B15*C15),0) -> 0.051306932 | O15: =IFERROR((F15*12)/B15,0) -> 0.0825 | P15: 400000 | Q15: =IFERROR(L15/P15,0) -> 0.010261386
A16: General | H16: =F16/12 -> 0 | I16: =IFERROR(F16*(1-G16),0) -> 0 | J16: =IFERROR(IF(D16=0,0,PMT(E16/12,D16*12,-(B16*(1-C16)))),0) -> 0 | K16: =IFERROR(I16-J16-H16,0) -> 0 | L16: =IFERROR(K16*12,0) -> 0 | M16: =IFERROR(L16/B16,0) -> 0 | N16: =IFERROR(L16/(B16*C16),0) -> 0 | O16: =IFERROR((F16*12)/B16,0) -> 0
A18: White = input cells (editable) | Gray/colored = formula cells (protected)
A20: Input Cells | B20: Formula Cells
A21: Editable | B21: Protected
A23: Addresses/Tenants anonymized for privacy

Sheet Rent Collections
A1: Date | B1: Property | C1: Tenant | D1: Amount due | E1: Amount collected | F1: Payment method | G1: Balance Remaining | H1: Notes | I1: Payment Status
A2: 46023 | B2: 412 Elmwood Drive | C2: Linda | D2: 800 | E2: 800 | F2: Cash | G2: =IF(D2="","",D2-E2) -> 0 | H2: AC Filter Replaced | I2: =IF(RentCollectionsTable[[#This Row],[Amount due]]="","",IF(RentCollectionsTable[[#This Row],[Balance Remaining]]>0,"Partial","Paid in full")) -> Paid in full
A3: 46023 | B3: 1053 Ridgeway Avenue | C3: Thomas | D3: 475 | E3: 475 | F3: Cash | G3: =IF(D3="","",D3-E3) -> 0 | H3: AC Filter Replaced | I3: =IF(RentCollectionsTable[[#This Row],[Amount due]]="","",IF(RentCollectionsTable[[#This Row],[Balance Remaining]]>0,"Partial","Paid in full")) -> Paid in full
A4: 46023 | B4: 215 Hollow Creek Road | C4: Aaron | D4: 900 | E4: 1050 | F4: Cash | G4: =IF(D4="","",D4-E4) -> -150 | H4: Replaced broken window (RESOLVED), paid for pet fee, AC Filter Replaced | I4: =IF(RentCollectionsTable[[#This Row],[Amount due]]="","",IF(RentCollectionsTable[[#This Row],[Balance Remaining]]>0,"Partial","Paid in full")) -> Paid in full
A5: 46024 | B5: 728 Chestnut Lane | C5: Michael | D5: 900 | E5: 900 | F5: Cash | G5: =IF(D5="","",D5-E5) -> 0 | H5: AC Filter Replaced | I5: =IF(RentCollectionsTable[[#This Row],[Amount due]]="","",IF(RentCollectionsTable[[#This Row],[Balance Remaining]]>0,"Partial","Paid in full")) -> Paid in full
A6: 46024 | B6: 634 Pinecrest Boulevard | C6: Dorothy | D6: 800 | E6: 800 | F6: Cash | G6: =IF(D6="","",D6-E6) -> 0 | H6: Wanted to renew lease early, AC Filter Replaced | I6: =IF(RentCollectionsTable[[#This Row],[Amount due]]="","",IF(RentCollectionsTable[[#This Row],[Balance Remaining]]>0,"Partial","Paid in full")) -> Paid in full
A7: 46024 | B7: 491 Maplewood Circle | C7: David | D7: 525 | E7: 525 | F7: Cash | G7: =IF(D7="","",D7-E7) -> 0 | H7: AC Filter Replaced | I7: =IF(RentCollectionsTable[[#This Row],[Amount due]]="","",IF(RentCollectionsTable[[#This Row],[Balance Remaining]]>0,"Partial","Paid in full")) -> Paid in full
A8: 46024 | B8: 1127 Cedarhill Drive | C8: James | D8: 850 | E8: 850 | F8: Cash | G8: =IF(D8="","",D8-E8) -> 0 | H8: AC Filter Replaced | I8: =IF(RentCollectionsTable[[#This Row],[Amount due]]="","",IF(RentCollectionsTable[[#This Row],[Balance Remaining]]>0,"Partial","Paid in full")) -> Paid in full
A9: 46024 | B9: 376 Walnut Grove Lane | C9: William | D9: 525 | E9: 525 | F9: Cash | G9: =IF(D9="","",D9-E9) -> 0 | H9: AC Filter Replaced | I9: =IF(RentCollectionsTable[[#This Row],[Amount due]]="","",IF(RentCollectionsTable[[#This Row],[Balance Remaining]]>0,"Partial","Paid in full")) -> Paid in full
A10: 46027 | B10: 309 Birchwood Court | C10: Patricia | D10: 750 | E10: 750 | F10: Cash | G10: =IF(D10="","",D10-E10) -> 0 | H10: AC Filter Replaced | I10: =IF(RentCollectionsTable[[#This Row],[Amount due]]="","",IF(RentCollectionsTable[[#This Row],[Balance Remaining]]>0,"Partial","Paid in full")) -> Paid in full
A11: 46028 | B11: 823 Thornberry Street | C11: Richard | D11: 850 | E11: 850 | F11: Cash | G11: =IF(D11="","",D11-E11) -> 0 | H11: AC Filter Replaced | I11: =IF(RentCollectionsTable[[#This Row],[Amount due]]="","",IF(RentCollectionsTable[[#This Row],[Balance Remaining]]>0,"Partial","Paid in full")) -> Paid in full
A12: 46036 | B12: 847 Sycamore Street | C12: Carol | D12: 900 | E12: 925 | F12: Cash | G12: =IF(D12="","",D12-E12) -> -25 | H12: Late fee paid | I12: =IF(RentCollectionsTable[[#This Row],[Amount due]]="","",IF(RentCollectionsTable[[#This Row],[Balance Remaining]]>0,"Partial","Paid in full")) -> Paid in full
A13: 46054 | B13: 412 Elmwood Drive | C13: Linda | D13: 800 | E13: 800 | F13: Cash | G13: =IF(D13="","",D13-E13) -> 0 | I13: =IF(RentCollectionsTable[[#This Row],[Amount due]]="","",IF(RentCollectionsTable[[#This Row],[Balance Remaining]]>0,"Partial","Paid in full")) -> Paid in full
A14: 46054 | B14: 1053 Ridgeway Avenue | C14: Thomas | D14: 475 | E14: 475 | F14: Cash | G14: =IF(D14="","",D14-E14) -> 0 | I14: =IF(RentCollectionsTable[[#This Row],[Amount due]]="","",IF(RentCollectionsTable[[#This Row],[Balance Remaining]]>0,"Partial","Paid in full")) -> Paid in full
A15: 46054 | B15: 847 Sycamore Street | C15: Carol | D15: 900 | E15: 1000 | F15: Cash | G15: =IF(D15="","",D15-E15) -> -100 | H15: Paid extra $100 by accident | I15: =IF(RentCollectionsTable[[#This Row],[Amount due]]="","",IF(RentCollectionsTable[[#This Row],[Balance Remaining]]>0,"Partial","Paid in full")) -> Paid in full
A16: 46054 | B16: 215 Hollow Creek Road | C16: Aaron | D16: 900 | E16: 900 | F16: Cash | G16: =IF(D16="","",D16-E16) -> 0 | I16: =IF(RentCollectionsTable[[#This Row],[Amount due]]="","",IF(RentCollectionsTable[[#This Row],[Balance Remaining]]>0,"Partial","Paid in full")) -> Paid in full
A17: 46054 | B17: 491 Maplewood Circle | C17: David | D17: 525 | E17: 525 | F17: Cash | G17: =IF(D17="","",D17-E17) -> 0 | I17: =IF(RentCollectionsTable[[#This Row],[Amount due]]="","",IF(RentCollectionsTable[[#This Row],[Balance Remaining]]>0,"Partial","Paid in full")) -> Paid in full
A18: 46054 | B18: 1127 Cedarhill Drive | C18: James | D18: 850 | E18: 850 | F18: Cash | G18: =IF(D18="","",D18-E18) -> 0 | H18: New electric water heater shut down, replaced fuses (RESOLVED) | I18: =IF(RentCollectionsTable[[#This Row],[Amount due]]="","",IF(RentCollectionsTable[[#This Row],[Balance Remaining]]>0,"Partial","Paid in full")) -> Paid in full
A19: 46055 | B19: 376 Walnut Grove Lane | C19: William | D19: 525 | E19: 525 | F19: Cash | G19: =IF(D19="","",D19-E19) -> 0 | I19: =IF(RentCollectionsTable[[#This Row],[Amount due]]="","",IF(RentCollectionsTable[[#This Row],[Balance Remaining]]>0,"Partial","Paid in full")) -> Paid in full
A20: 46056 | B20: 823 Thornberry Street | C20: Richard | D20: 850 | E20: 850 | F20: Cash | G20: =IF(D20="","",D20-E20) -> 0 | I20: =IF(RentCollectionsTable[[#This Row],[Amount due]]="","",IF(RentCollectionsTable[[#This Row],[Balance Remaining]]>0,"Partial","Paid in full")) -> Paid in full
A21: 46059 | B21: 728 Chestnut Lane | C21: Michael | D21: 900 | E21: 900 | F21: Cash | G21: =IF(D21="","",D21-E21) -> 0 | I21: =IF(RentCollectionsTable[[#This Row],[Amount due]]="","",IF(RentCollectionsTable[[#This Row],[Balance Remaining]]>0,"Partial","Paid in full")) -> Paid in full
A22: 46059 | B22: 309 Birchwood Court | C22: Patricia | D22: 750 | E22: 750 | F22: Cash | G22: =IF(D22="","",D22-E22) -> 0 | I22: =IF(RentCollectionsTable[[#This Row],[Amount due]]="","",IF(RentCollectionsTable[[#This Row],[Balance Remaining]]>0,"Partial","Paid in full")) -> Paid in full
A23: 46059 | B23: 634 Pinecrest Boulevard | C23: Dorothy | D23: 800 | E23: 800 | F23: Cash | G23: =IF(D23="","",D23-E23) -> 0 | I23: =IF(RentCollectionsTable[[#This Row],[Amount due]]="","",IF(RentCollectionsTable[[#This Row],[Balance Remaining]]>0,"Partial","Paid in full")) -> Paid in full
A24: 46082 | B24: 412 Elmwood Drive | C24: Linda | D24: 800 | E24: 800 | F24: Cash | G24: =IF(D24="","",D24-E24) -> 0 | I24: =IF(RentCollectionsTable[[#This Row],[Amount due]]="","",IF(RentCollectionsTable[[#This Row],[Balance Remaining]]>0,"Partial","Paid in full")) -> Paid in full
A25: 46082 | B25: 1053 Ridgeway Avenue | C25: Thomas | D25: 475 | E25: 475 | F25: Cash | G25: =IF(D25="","",D25-E25) -> 0 | I25: =IF(RentCollectionsTable[[#This Row],[Amount due]]="","",IF(RentCollectionsTable[[#This Row],[Balance Remaining]]>0,"Partial","Paid in full")) -> Paid in full
A26: 46082 | B26: 1127 Cedarhill Drive | C26: James | D26: 850 | E26: 850 | F26: Cash | G26: =IF(D26="","",D26-E26) -> 0 | I26: =IF(RentCollectionsTable[[#This Row],[Amount due]]="","",IF(RentCollectionsTable[[#This Row],[Balance Remaining]]>0,"Partial","Paid in full")) -> Paid in full
A27: 46083 | B27: 376 Walnut Grove Lane | C27: William | D27: 525 | E27: 525 | F27: Cash | G27: =IF(D27="","",D27-E27) -> 0 | I27: =IF(RentCollectionsTable[[#This Row],[Amount due]]="","",IF(RentCollectionsTable[[#This Row],[Balance Remaining]]>0,"Partial","Paid in full")) -> Paid in full
A28: 46084 | B28: 491 Maplewood Circle | C28: David | D28: 525 | E28: 525 | F28: Cash | G28: =IF(D28="","",D28-E28) -> 0 | I28: =IF(RentCollectionsTable[[#This Row],[Amount due]]="","",IF(RentCollectionsTable[[#This Row],[Balance Remaining]]>0,"Partial","Paid in full")) -> Paid in full
A29: 46084 | B29: 823 Thornberry Street | C29: Richard | D29: 850 | E29: 850 | F29: Cash | G29: =IF(D29="","",D29-E29) -> 0 | I29: =IF(RentCollectionsTable[[#This Row],[Amount due]]="","",IF(RentCollectionsTable[[#This Row],[Balance Remaining]]>0,"Partial","Paid in full")) -> Paid in full
A30: 46086 | B30: 309 Birchwood Court | C30: Patricia | D30: 750 | E30: 750 | F30: Cash | G30: =IF(D30="","",D30-E30) -> 0 | I30: =IF(RentCollectionsTable[[#This Row],[Amount due]]="","",IF(RentCollectionsTable[[#This Row],[Balance Remaining]]>0,"Partial","Paid in full")) -> Paid in full
... A33: 46087 | B33: 634 Pinecrest Boulevard | C33: Dorothy | D33: 800 | E33: 800 | F33: Cash | G33: =IF(D33="","",D33-E33) -> 0 | I33: =IF(RentCollectionsTable[[#This Row],[Amount due]]="","",IF(RentCollectionsTable[[#This Row],[Balance Remaining]]>0,"Partial","Paid in full")) -> Paid in full
A34: 46096 | B34: 215 Hollow Creek Road | C34: Aaron | D34: 900 | E34: 925 | F34: Cash | G34: =IF(D34="","",D34-E34) -> -25 | H34: Late fee paid | I34: =IF(RentCollectionsTable[[#This Row],[Amount due]]="","",IF(RentCollectionsTable[[#This Row],[Balance Remaining]]>0,"Partial","Paid in full")) -> Paid in full
A35: 46113 | B35: 412 Elmwood Drive | C35: Linda | D35: 800 | E35: 800 | F35: Cash | G35: =IF(D35="","",D35-E35) -> 0 | H35: Requested lease renewal but only in her name, not husband (She feels like husband does not help with bills) | I35: =IF(RentCollectionsTable[[#This Row],[Amount due]]="","",IF(RentCollectionsTable[[#This Row],[Balance Remaining]]>0,"Partial","Paid in full")) -> Paid in full
A36: 46113 | B36: 1053 Ridgeway Avenue | C36: Thomas | D36: 475 | E36: 475 | F36: Cash | G36: =IF(D36="","",D36-E36) -> 0 | H36: AC Filter Replaced | I36: =IF(RentCollectionsTable[[#This Row],[Amount due]]="","",IF(RentCollectionsTable[[#This Row],[Balance Remaining]]>0,"Partial","Paid in full")) -> Paid in full
A37: 46113 | B37: 309 Birchwood Court | C37: Patricia | D37: 750 | E37: 750 | F37: Cash | G37: =IF(D37="","",D37-E37) -> 0 | H37: AC Filter Replaced | I37: =IF(RentCollectionsTable[[#This Row],[Amount due]]="","",IF(RentCollectionsTable[[#This Row],[Balance Remaining]]>0,"Partial","Paid in full")) -> Paid in full
A38: 46113 | B38: 215 Hollow Creek Road | C38: Aaron | D38: 900 | E38: 900 | F38: Cash | G38: =IF(D38="","",D38-E38) -> 0 | H38: AC Filter Replaced | I38: =IF(RentCollectionsTable[[#This Row],[Amount due]]="","",IF(RentCollectionsTable[[#This Row],[Balance Remaining]]>0,"Partial","Paid in full")) -> Paid in full
A39: 46113 | B39: 1127 Cedarhill Drive | C39: James | D39: 850 | E39: 850 | F39: Cash | G39: =IF(D39="","",D39-E39) -> 0 | H39: AC Filter Replaced | I39: =IF(RentCollectionsTable[[#This Row],[Amount due]]="","",IF(RentCollectionsTable[[#This Row],[Balance Remaining]]>0,"Partial","Paid in full")) -> Paid in full
A40: 46114 | B40: 823 Thornberry Street | C40: Richard | D40: 850 | E40: 850 | F40: Cash | G40: =IF(D40="","",D40-E40) -> 0 | H40: AC Filter Replaced | I40: =IF(RentCollectionsTable[[#This Row],[Amount due]]="","",IF(RentCollectionsTable[[#This Row],[Balance Remaining]]>0,"Partial","Paid in full")) -> Paid in full
A41: 46115 | B41: 728 Chestnut Lane | C41: Michael | D41: 900 | E41: 900 | F41: Cash | G41: =IF(D41="","",D41-E41) -> 0 | H41: AC Filter Replaced | I41: =IF(RentCollectionsTable[[#This Row],[Amount due]]="","",IF(RentCollectionsTable[[#This Row],[Balance Remaining]]>0,"Partial","Paid in full")) -> Paid in full
A42: 46117 | B42: 634 Pinecrest Boulevard | C42: Dorothy | D42: 800 | E42: 800 | F42: Cash | G42: =IF(D42="","",D42-E42) -> 0 | H42: AC Filter Replaced | I42: =IF(RentCollectionsTable[[#This Row],[Amount due]]="","",IF(RentCollectionsTable[[#This Row],[Balance Remaining]]>0,"Partial","Paid in full")) -> Paid in full
...

Sheet Expenses
A1: Date | B1: Property | C1: Category | D1: Vendor | E1: Amount | F1: Description | G1: Notes | H1: Month | I1: Year
A2: 46023 | B2: 1127 Cedarhill Drive | C2: Maintenance | D2: ACE Hardware | E2: 38.95 | F2: Front/Back lock/handle kit | H2: =TEXT(A2,"MM-MMM") -> 01-Jan | I2: =TEXT(A2,"YYYY") -> 2026
A3: 46028 | B3: General | C3: Miscellaneous | D3: Home Depot | E3: -165.83 | F3: Returns - mixed properties | H3: =TEXT(A3,"MM-MMM") -> 01-Jan | I3: =TEXT(A3,"YYYY") -> 2026
A4: 46035 | B4: 412 Elmwood Drive | C4: Repair | D4: Home Depot | E4: 7.64 | F4: Lightbulb replacement (bathroom) | H4: =TEXT(A4,"MM-MMM") -> 01-Jan | I4: =TEXT(A4,"YYYY") -> 2026
A5: 46035 | B5: 412 Elmwood Drive | C5: Repair | D5: Home Depot | E5: 6.55 | F5: Lightbulb replacement (Kitchen) | H5: =TEXT(A5,"MM-MMM") -> 01-Jan | I5: =TEXT(A5,"YYYY") -> 2026
A6: 46037 | B6: 634 Pinecrest Boulevard | C6: Repair | D6: ACE Hardware | E6: 19.57 | F6: 35/5 Capacitor | H6: =TEXT(A6,"MM-MMM") -> 01-Jan | I6: =TEXT(A6,"YYYY") -> 2026
A7: 46045 | B7: General | C7: Miscellaneous | D7: Home Depot | E7: -24.99 | F7: Returns - mixed properties | H7: =TEXT(A7,"MM-MMM") -> 01-Jan | I7: =TEXT(A7,"YYYY") -> 2026
A8: 46056 | B8: 1127 Cedarhill Drive | C8: Repair | D8: Home Depot | E8: 54.71 | F8: New thermostat | G8: Blower fan stays on, no heat | H8: =TEXT(A8,"MM-MMM") -> 02-Feb | I8: =TEXT(A8,"YYYY") -> 2026
A9: 46058 | B9: 412 Elmwood Drive | C9: Repair | D9: Home Depot | E9: 361.79 | F9: Delta cartridge failure | G9: Complained no hot water to shower only | H9: =TEXT(A9,"MM-MMM") -> 02-Feb | I9: =TEXT(A9,"YYYY") -> 2026
A10: 46066 | B10: 1127 Cedarhill Drive | C10: Capital Improvement | D10: Home Depot | E10: 785.63 | F10: Rheem 40-gallon electric, two supply valves | G10: Eric handyman, $200 for labor | H10: =TEXT(A10,"MM-MMM") -> 02-Feb | I10: =TEXT(A10,"YYYY") -> 2026
A11: 46093 | B11: 309 Birchwood Court | C11: Repair | D11: Home Depot | E11: 47.57 | F11: Shower cartridge rubber seat failure | G11: Shower leaking, drips | H11: =TEXT(A11,"MM-MMM") -> 03-Mar | I11: =TEXT(A11,"YYYY") -> 2026
A12: 46100 | B12: 309 Birchwood Court | C12: Repair | D12: Home Depot | E12: 47.02 | F12: Shower cartridge failure | G12: Shower leaking, drips | H12: =TEXT(A12,"MM-MMM") -> 03-Mar | I12: =TEXT(A12,"YYYY") -> 2026
A13: 46100 | B13: General | C13: Miscellaneous | D13: Home Depot | E13: -494.7 | F13: Returns - mixed properties | H13: =TEXT(A13,"MM-MMM") -> 03-Mar | I13: =TEXT(A13,"YYYY") -> 2026
A14: 46105 | B14: 215 Hollow Creek Road | C14: Repair | D14: AGM | E14: 286.57 | F14: Double-pane window, bottom sash | G14: 27 3/4L x 28 1/2W, 3/8 | H14: =TEXT(A14,"MM-MMM") -> 03-Mar | I14: =TEXT(A14,"YYYY") -> 2026
A15: 46106 | B15: 215 Hollow Creek Road | C15: Repair | D15: Home Depot | E15: 59.62 | F15: Tools to fix front window | H15: =TEXT(A15,"MM-MMM") -> 03-Mar | I15: =TEXT(A15,"YYYY") -> 2026
A16: 46107 | B16: 215 Hollow Creek Road | C16: Repair | D16: Home Depot | E16: 18.29 | F16: Silicone adhesive for front window | H16: =TEXT(A16,"MM-MMM") -> 03-Mar | I16: =TEXT(A16,"YYYY") -> 2026
A17: 46118 | B17: 215 Hollow Creek Road | C17: Repair | D17: Home Depot | E17: 50.26 | F17: Additional parts/tools to fix window | H17: =TEXT(A17,"MM-MMM") -> 04-Apr | I17: =TEXT(A17,"YYYY") -> 2026
A18: 46155 | B18: 847 Sycamore Street | C18: Repair | D18: Sharps Electric | E18: 3000 | F18: Electrical meter/disconnect install, smoke detectors (insurance claim) | H18: =TEXT(A18,"MM-MMM") -> 05-May | I18: =TEXT(A18,"YYYY") -> 2026
A19: 46157 | B19: 847 Sycamore Street | C19: Repair | D19: GEICO | E19: -2811.15 | F19: Insurance Reimbursement | G19: Electrical, Tree, Fence | H19: =TEXT(A19,"MM-MMM") -> 05-May | I19: =TEXT(A19,"YYYY") -> 2026

Sheet Expense Analysis
A1: Expense Analysis by Category
A3: Category | B3: Sum of Amount
A4: Capital Improvement | B4: 785.63
A5: Maintenance | B5: 38.95
A6: Miscellaneous | B6: -685.52
A7: Repair | B7: 1148.44
A8: Grand Total | B8: 1287.5
A10: Expense Analysis by Total
A12: Sum of Amount | C12: Month
A13: Property | B13: Category | C13: 01-Jan | D13: 02-Feb | E13: 03-Mar | F13: 04-Apr | G13: 05-May | H13: Grand Total
A14: 1127 Cedarhill Drive | C14: 38.95 | D14: 840.34 | H14: 879.29
A15: 215 Hollow Creek Road | E15: 364.48 | F15: 50.26 | H15: 414.74
A16: 309 Birchwood Court | E16: 94.59 | H16: 94.59
A17: 412 Elmwood Drive | C17: 14.19 | D17: 361.79 | H17: 375.98
A18: 634 Pinecrest Boulevard | C18: 19.57 | H18: 19.57
A19: 847 Sycamore Street | G19: 188.85 | H19: 188.85
A20: General | C20: -190.82 | E20: -494.7 | H20: -685.52
A21: Grand Total | C21: -118.11 | D21: 1202.13 | E21: -35.63 | F21: 50.26 | G21: 188.85 | H21: 1287.5
